Workbook

Sheet Sheet1
B2: 100
A3: T | B3: 350 | C3: 450 | D3: 500 | E3: 600 | G3: T | H3: U
A4: H | B4: 1200.4 | C4: 1253.7 | D4: 1278.6 | E4: 1327.9 | G4: {=TRANSPOSE(B3:E3)} -> 350 | H4: {=TRANSPOSE(B6:E6)} -> 1115.4251
A5: V | B5: 4.592 | C5: 5.266 | D5: 5.589 | E5: 6.217 | G5: 450 | H5: 1156.2528 | Q5: Theta | R5: =PI()*3/2 -> 4.712389
A6: U | B6: =B4-($B$2*B5)/5.40395 -> 1115.4251 | C6: =C4-($B$2*C5)/5.40395 -> 1156.2528 | D6: =D4-($B$2*D5)/5.40395 -> 1175.1757 | E6: =E4-($B$2*E5)/5.40395 -> 1212.8545 | G6: 500 | H6: 1175.1757
G7: 600 | H7: 1212.8545 | Q7: R(z)(theta) | R7: =COS(R5) -> 0 | S7: =-SIN(R5) -> 1 | T7: 0
R8: =SIN(R5) -> -1 | S8: =COS(R5) -> 0 | T8: 0
R9: 0 | S9: 0 | T9: 1
E43: Goal | F43: 100000000000000 | G43: Time | H43: =IF(F44=0,(F43/(F46*F47)/60),((F43+F45*(1.16)^F44)/((F46+F44)*F47))/60) -> 43.507091
E44: Upgrade amount | F44: 7.4210913 | G44: Time w/o ups | H44: =(F43/(F46*F47)/60) -> 53.418803
E45: Initial Upgrade rate | F45: 60800000000000
E46: Initial level | F46: 3
E47: Rate / unit | F47: 10400000000 | G47: Initial Prod | H47: =F46*F47 -> 31200000000
E48: Final level | F48: =Roundup(F46+F44) -> 11 | G48: Final Prod | H48: =F48*F47 -> 114400000000
E50: Goal | F50: 40000000000000 | G50: Time | H50: =IF(F51=0,(F50/(F53*F54)/60),((F50+F52*(1.16)^F51)/((F53+F51)*F54))/60) -> 11.990408
E51: Upgrade amount | F51: 0 | G51: Time w/o ups | H51: =(F50/(F53*F54)/60) -> 11.990408
E52: Initial Upgrade rate | F52: 80400000000
E53: Initial level | F53: 40
E54: Rate / unit | F54: 1390000000 | G54: Initial Prod | H54: =F53*F54 -> 55600000000
E55: Final level | F55: =Roundup(F53+F51) -> 40 | G55: Final Prod | H55: =F55*F54 -> 55600000000
B62: X | C62: Y
B63: 30 | C63: 72
B64: 40 | C64: 67 | E64: {=LINEST(C63:C67,B63:B67,1,1)} -> -0.72 | F64: 95.6
B65: 50 | C65: 62 | E65: 0.094516313 | F65: 4.9112117
B66: 60 | C66: 55 | E66: 0.95084373 | F66: 2.9888682
B67: 70 | C67: 42 | E67: 58.029851 | F67: 3
E68: 518.4 | F68: 26.8
A85: Thermo
B86: T_H (K) | C86: T_C | D86: COP
B87: 300 | C87: 0 | D87: =C87/(B87-C87) -> 0
B88: 300 | C88: 5 | D88: =C88/(B88-C88) -> 0.016949153
B89: 300 | C89: 10 | D89: =C89/(B89-C89) -> 0.034482759
B90: 300 | C90: 15 | D90: =C90/(B90-C90) -> 0.052631579
B91: 300 | C91: 20 | D91: =C91/(B91-C91) -> 0.071428571
B92: 300 | C92: 25 | D92: =C92/(B92-C92) -> 0.090909091
B93: 300 | C93: 30 | D93: =C93/(B93-C93) -> 0.11111111
B94: 300 | C94: 35 | D94: =C94/(B94-C94) -> 0.13207547
B95: 300 | C95: 40 | D95: =C95/(B95-C95) -> 0.15384615
B96: 300 | C96: 45 | D96: =C96/(B96-C96) -> 0.17647059
B97: 300 | C97: 50 | D97: =C97/(B97-C97) -> 0.2
...

Sheet __Solver__
A1: 2023951696517264728 | C1: =Sheet1!F44 <= Sheet1!F440 -> FALSE | D1: up4IUcoNtrCHgZy | J1: 1
A2: =Min(Sheet1!H43) -> 43.507091
A3: =Sheet1!F44 -> 7.4210913
A4: MiJz | B4: MiJz
A6: Rg==
A7: =Sheet1!F44 <= 0 -> FALSE

Sheet __Solver___conflict655888643

Sheet __Solver___conflict370605657

Sheet __Solver___conflict920513822
A2: =Max(Sheet1!A1) -> 0

Sheet __Solver___conflict1054973960

Sheet __Solver___conflict2083569777

Sheet __Solver___conflict257838993
